Workbook

Sheet SUMMARY_-_GCM
A1: ATTENDANCE SUMMARY REPORT
A2: (To be Accomplished by GCM)
A4: GROUP CHAPEL MANAGER | D4: PAMARAN, DENNIS | N4: DATE SUBMITTED
A5: PERIOD COVERED | D5: October 1-15, 2026 | N5: REGION | Q5: MW1 & 2
A6: SEQ # | B6: EMPLOYEE NAME | C6: DESIGNATION | D6: CHAPEL | E6: TOTAL WORKING DAYS | G6: VL | I6: SL | K6: ML/PL* | M6: ABSENCES | O6: TARDINESS | Q6: REMARKS
F7: SCHEDULE | G7: DATE | H7: # OF DAYS | I7: DATE | J7: # OF DAYS | K7: DATE | L7: # OF DAYS | M7: DATE | N7: # OF ABSENCES | O7: DATE | P7: # OF
P8: HRS/MIN
A9: 1 | B9: DENNIS Q. PAMARAN | C9: GCM | D9: MWT | E9: =ZAMBOANGA!C26 -> 0 | F9: 8AM – 5PM | H9: =ZAMBOANGA!C28 -> 0 | J9: =ZAMBOANGA!C29 -> 0 | L9: =ZAMBOANGA!C30 -> 0 | N9: =ZAMBOANGA!C27 -> 0
A10: 2 | B10: DIVINE GRACE CARBONELL | C10: CM | D10: PAGADIAN/BUUG | E10: =PAGADIAN!C26 -> 0 | F10: 8AM – 5PM | H10: =PAGADIAN!C28 -> 0 | J10: =PAGADIAN!C29 -> 0 | L10: =PAGADIAN!C30 -> 0 | N10: =PAGADIAN!C27 -> 0
A11: 3 | B11: GILBERT DELA CRUZ | C11: CM | D11: Oroquieta | E11: =OROQUIETA!C26 -> 0 | F11: 8AM – 5PM | H11: =OROQUIETA!C28 -> 0 | J11: =OROQUIETA!C29 -> 0 | L11: =OROQUIETA!C30 -> 0 | N11: =OROQUIETA!C27 -> 0
A12: 4 | B12: EDUARDO BARICCA | C12: CM | D12: TANGUB | E12: =TANGUB!C26 -> 0 | F12: 8AM – 5PM | H12: =TANGUB!C28 -> 0 | J12: =TANGUB!C29 -> 0 | L12: =TANGUB!C30 -> 0 | N12: =TANGUB!C27 -> 0
A13: 5 | B13: MARJORIE BAUTISTA | C13: CM | D13: IPIL | E13: =IPIL!C26 -> 0 | F13: 8AM – 5PM | H13: =IPIL!C28 -> 0 | J13: =IPIL!C29 -> 0 | L13: =IPIL!C30 -> 0 | N13: =IPIL!C27 -> 0
A14: 6 | B14: EMMYLOU MARIANO | C14: CM | D14: ZAMBOANGA | E14: =ZAMBOANGA!C26 -> 0 | F14: 8AM – 5PM | H14: =ZAMBOANGA!G28 -> 0 | J14: =ZAMBOANGA!G29 -> 0 | L14: =ZAMBOANGA!G30 -> 0 | N14: =ZAMBOANGA!G27 -> 0
A15: 7 | B15: ADRIAN DR. SUSON | C15: GCM Staff | D15: ZAMBOANGA | E15: =ZAMBOANGA!AA26 -> 0 | F15: 8AM – 5PM | H15: =ZAMBOANGA!AA28 -> 0 | J15: =ZAMBOANGA!AA29 -> 0 | L15: =ZAMBOANGA!AA30 -> 0 | N15: =ZAMBOANGA!AA27 -> 0
A16: 8 | B16: LENIE MAY AUSEJO | C16: FCR | D16: ZAMBOANGA | E16: =ZAMBOANGA!W26 -> 0 | F16: weekly shifting | H16: =ZAMBOANGA!W28 -> 0 | J16: =ZAMBOANGA!W29 -> 0 | L16: =ZAMBOANGA!W30 -> 0 | N16: =ZAMBOANGA!W27 -> 0
A17: 9 | B17: SHEILA VILLANO | C17: FCR | D17: ZAMBOANGA | E17: =ZAMBOANGA!K26 -> 0 | F17: weekly shifting | H17: =ZAMBOANGA!K28 -> 0 | J17: =ZAMBOANGA!K29 -> 0 | L17: =ZAMBOANGA!K30 -> 0 | N17: =ZAMBOANGA!K27 -> 0
A18: 10 | B18: ROWELL MENDIJA | C18: FCR | D18: ZAMBOANGA | E18: =ZAMBOANGA!O26 -> 0 | F18: weekly shifting | H18: =ZAMBOANGA!O28 -> 0 | J18: =ZAMBOANGA!O29 -> 0 | L18: =ZAMBOANGA!O30 -> 0 | N18: =ZAMBOANGA!O27 -> 0
A19: 11 | B19: DANICA MAE LEDESMA | C19: FCR | D19: ZAMBOANGA | E19: =ZAMBOANGA!S26 -> 0 | F19: weekly shifting | H19: =ZAMBOANGA!S28 -> 0 | J19: =ZAMBOANGA!S29 -> 0 | L19: =ZAMBOANGA!S30 -> 0 | N19: =ZAMBOANGA!S27 -> 0
A20: 12 | B20: DEAN VINCENT TAMPARONG | C20: FCR | D20: PAGADIAN | E20: =PAGADIAN!AA26 -> 0 | F20: weekly shifting | H20: =PAGADIAN!AA28 -> 0 | J20: =PAGADIAN!AA29 -> 0 | L20: =PAGADIAN!AA30 -> 0 | N20: =PAGADIAN!AA27 -> 0
A21: 13 | B21: KIESHA CHARISSE BELLOAN | C21: FCR | D21: PAGADIAN | E21: =PAGADIAN!AE26 -> 0 | F21: weekly shifting | H21: =PAGADIAN!AE28 -> 0 | J21: =PAGADIAN!AE29 -> 0 | L21: =PAGADIAN!AE30 -> 0 | N21: =PAGADIAN!AE27 -> 0
A22: 14 | B22: RUBEN QUIPTE | C22: Driver | D22: Buug | E22: =BUUG!C26 -> 0 | F22: weekly shifting | H22: =COUNTIF(BUUG!C9:C23,"VL")+COUNTIF(BUUG!C9:C23,"Leave") -> 0 | J22: =BUUG!C29 -> 0 | L22: =BUUG!C30 -> 0 | N22: =BUUG!C27 -> 0
A23: 15 | B23: JOEL PANTUJAN | C23: Driver | D23: TANGUB | E23: =TANGUB!K26 -> 0 | F23: weekly shifting | H23: =TANGUB!K28 -> 0 | J23: =TANGUB!K29 -> 0 | L23: =TANGUB!K30 -> 0 | N23: =TANGUB!K27 -> 0
A24: 16 | B24: JUSIL ANTIPUESTO | C24: Driver | D24: Oroquieta | E24: =OROQUIETA!K26 -> 0 | F24: 8AM – 5PM | H24: =OROQUIETA!K28 -> 0 | J24: =OROQUIETA!K29 -> 0 | L24: =OROQUIETA!K30 -> 0 | N24: =OROQUIETA!K27 -> 0
A25: 17 | B25: CARY VILLANO | C25: Driver | D25: Ipil | E25: =IPIL!S26 -> 0 | F25: weekly shifting | H25: =IPIL!S28 -> 0 | J25: =IPIL!S29 -> 0 | L25: =IPIL!S30 -> 0 | N25: =IPIL!S27 -> 0
A26: 18 | B26: GREGORIO MATIAS | C26: Embalmer | D26: ZAMBOANGA | E26: =ZAMBOANGA!BG26 -> 0 | F26: weekly shifting | H26: =ZAMBOANGA!BG28 -> 0 | J26: =ZAMBOANGA!BG29 -> 0 | L26: =ZAMBOANGA!BG30 -> 0 | N26: =ZAMBOANGA!BG27 -> 0
A27: 19 | B27: ERNIE DICO | C27: Embalmer | D27: TANGUB | E27: =TANGUB!G26 -> 0 | F27: weekly shifting | H27: =TANGUB!G28 -> 0 | J27: =TANGUB!G29 -> 0 | L27: =TANGUB!G30 -> 0 | N27: =TANGUB!G27 -> 0
A28: 20 | B28: DANIEL LAYOGUE | C28: Embalmer | D28: IPIL | E28: =IPIL!G26 -> 0 | F28: weekly shifting | H28: =IPIL!G28 -> 0 | J28: =IPIL!G29 -> 0 | L28: =IPIL!G30 -> 0 | N28: =IPIL!G27 -> 0
A29: 21 | B29: GLESERIO PAQUIBO | C29: Embalmer | D29: IPIL | E29: =IPIL!K26 -> 0 | F29: weekly shifting | H29: =IPIL!K28 -> 0 | J29: =IPIL!K29 -> 0 | L29: =IPIL!K30 -> 0 | N29: =IPIL!K27 -> 0
A30: 22 | B30: MICHAEL ARCH DANIEL | C30: Embalmer | D30: TANGUB | E30: =TANGUB!S26 -> 0 | F30: weekly shifting | H30: =TANGUB!S28 -> 0 | J30: =TANGUB!S29 -> 0 | L30: =TANGUB!S30 -> 0 | N30: =TANGUB!S27 -> 0
A31: 23 | B31: ENGELINE MAE TRIBUNALO | C31: Attendant | D31: PAGADIAN | E31: =PAGADIAN!G26 -> 0 | F31: weekly shifting | H31: =PAGADIAN!G28 -> 0 | J31: =PAGADIAN!G29 -> 0 | L31: =PAGADIAN!G30 -> 0 | N31: =PAGADIAN!G27 -> 0
A32: 24 | B32: FREDE BERONDO | C32: Attendant | D32: PAGADIAN | E32: =PAGADIAN!K26 -> 0 | F32: weekly shifting | H32: =PAGADIAN!K28 -> 0 | J32: =PAGADIAN!K29 -> 0 | L32: =PAGADIAN!K30 -> 0 | N32: =PAGADIAN!K27 -> 0
A33: 25 | B33: ROMEL MANUEL | C33: Attendant | D33: ZAMBOANGA | E33: =ZAMBOANGA!AY26 -> 0 | F33: weekly shifting | H33: =ZAMBOANGA!AY28 -> 0 | J33: =ZAMBOANGA!AY29 -> 0 | L33: =ZAMBOANGA!AY30 -> 0 | N33: =ZAMBOANGA!AY27 -> 0
A34: 26 | B34: ROMANO CANTIGA | C34: Attendant | D34: IPIL | E34: =IPIL!W26 -> 0 | F34: weekly shifting | H34: =IPIL!W28 -> 0 | J34: =IPIL!W29 -> 0 | L34: =IPIL!W30 -> 0 | N34: =IPIL!W27 -> 0
A35: 27 | B35: JEFFREY DELOS REYES | C35: Attendant | D35: ZAMBOANGA | E35: =ZAMBOANGA!CU26 -> 0 | F35: weekly shifting | H35: =ZAMBOANGA!CU28 -> 0 | J35: =ZAMBOANGA!CU29 -> 0 | L35: =ZAMBOANGA!CU30 -> 0 | N35: =ZAMBOANGA!CU27 -> 0
A36: 28 | B36: SUNNY CASTOR | C36: Attendant | D36: ZAMBOANGA | E36: =ZAMBOANGA!CQ26 -> 0 | F36: weekly shifting | H36: =ZAMBOANGA!CQ28 -> 0 | J36: =ZAMBOANGA!CQ29 -> 0 | L36: =ZAMBOANGA!CQ30 -> 0 | N36: =ZAMBOANGA!CQ27 -> 0
A37: 29 | B37: SANTIE ALFON | C37: Attendant | D37: ZAMBOANGA | E37: =ZAMBOANGA!BW26 -> 0 | F37: weekly shifting | H37: =ZAMBOANGA!BW28 -> 0 | J37: =ZAMBOANGA!BW29 -> 0 | L37: =ZAMBOANGA!BW30 -> 0 | N37: =ZAMBOANGA!BW27 -> 0
A38: 30 | B38: JOEY DELA CRUZ | C38: Astt Embalmer | D38: ZAMBOANGA | E38: =ZAMBOANGA!BO26 -> 0 | F38: weekly shifting | H38: =ZAMBOANGA!BO28 -> 0 | J38: =ZAMBOANGA!BO29 -> 0 | L38: =ZAMBOANGA!BO30 -> 0 | N38: =ZAMBOANGA!BO27 -> 0
A39: 31 | B39: LOLIBOY ALMEDA | C39: Attendant/Asst Embalmer | D39: Ipil | E39: =IPIL!O26 -> 0 | F39: weekly shifting | H39: =IPIL!O28 -> 0 | J39: =IPIL!O29 -> 0 | L39: =IPIL!O30 -> 0 | N39: =IPIL!O27 -> 0
A40: 32 | B40: JUVEN ANTIPUESTO | C40: Attendant/Asst Embalmer | D40: Oroquieta | E40: =OROQUIETA!W26 -> 0 | F40: 8AM – 5PM | H40: =OROQUIETA!W28 -> 0 | J40: =OROQUIETA!W29 -> 0 | L40: =OROQUIETA!W30 -> 0 | N40: =OROQUIETA!W27 -> 0
A41: 33 | B41: HANZ CALAPIZ | C41: Attendant/Asst Embalmer | D41: Oroquieta | E41: =OROQUIETA!O26 -> 0 | F41: 8AM – 5PM | H41: =OROQUIETA!O28 -> 0 | J41: =OROQUIETA!O29 -> 0 | L41: =OROQUIETA!O30 -> 0 | N41: =OROQUIETA!O27 -> 0
...

Sheet BUUG
A1: CHAPEL MANAGER | C1: DIVINE GRACE P. CARBONELL
A2: REGION | C2: MW1
A3: CHAPEL | C3: BUUG
A4: PERIOD | C4: =CLEAN('SUMMARY_-_GCM'!D5) -> October 1-15, 2026
A7: DATE | C7: RUBEN QUIPTE | E7: Shifting Schedule | G7: IAN MORANDARTE | I7: Shifting Schedule
A8: # | B8: DAY | C8: IN | D8: OUT | E8: IN | F8: OUT | G8: IN | H8: OUT | I8: IN | J8: OUT
A26: WORKED DAYS | C26: =COUNT(C9:C23) -> 0 | G26: =COUNT(G9:G23) -> 0
A27: ABSENCES | C27: =COUNTIF(C9:C23,"Absent") -> 0 | G27: =COUNTIF(G9:G23,"Absent") -> 0
A28: VL | C28: =COUNTIF(C9:C23,"Leave")+COUNTIF(C9:C23,"VL") -> 0 | G28: =COUNTIF(G9:G23,"Leave")+COUNTIF(G9:G23,"VL") -> 0
A29: SL | C29: =COUNTIF(C9:C23,"SL") -> 0 | G29: =COUNTIF(G9:G23,"SL") -> 0
A30: ML | C30: =COUNTIF(C9:C23,"ML") -> 0 | G30: =COUNTIF(G9:G23,"ML") -> 0

Sheet PAGADIAN
A1: CHAPEL MANAGER | C1: Carbonell, Divine Grace P.
A2: REGION | C2: MW1
A3: CHAPEL | C3: PAGADIAN
A4: PERIOD | C4: =CLEAN('SUMMARY_-_GCM'!D5) -> October 1-15, 2026
A7: DATE | C7: DIVINE GRACE CARBONELL | E7: Shifting Schedule | G7: ENGELINE MAE TRIBUNALO | I7: Shifting Schedule | K7: FREDE BERONDO | M7: Shifting Schedule | O7: JULIETO QUINTANA | Q7: Shifting Schedule | S7: JASON DE ASIS | U7: Shifting Schedule | W7: JEFFREY OGOCIERDO | Y7: Shifting Schedule | AA7: DEAN VINCENT TAMPARONG | AC7: Shifting Schedule | AE7: KIESHA CHARISSE BELLOAN | AG7: Shifting Schedule | AI7: DANDY TARIMAN | AK7: Shifting Schedule | AM7: JHON TERRYS LADEZA | AO7: Shifting Schedule
A8: =CLEAN(BUUG!A8) -> # | B8: DAY | C8: IN | D8: OUT | E8: IN | F8: OUT | G8: IN | H8: OUT | I8: IN | J8: OUT | K8: IN | L8: OUT | M8: IN | N8: OUT | O8: IN | P8: OUT | Q8: IN | R8: OUT | S8: IN | T8: OUT | U8: IN | V8: OUT | W8: IN | X8: OUT | Y8: IN | Z8: OUT | AA8: IN | AB8: OUT | AC8: IN | AD8: OUT | AE8: IN | AF8: OUT | AG8: IN | AH8: OUT | AI8: IN | AJ8: OUT | AK8: IN | AL8: OUT | AM8: IN | AN8: OUT | AO8: IN | AP8: OUT
A26: WORKED DAYS | C26: =COUNT(C9:C24) -> 0 | G26: =COUNT(G9:G24) -> 0 | K26: =COUNT(K9:K24) -> 0 | O26: =COUNT(O9:O24) -> 0 | S26: =COUNT(S9:S24) -> 0 | W26: =COUNT(W9:W24) -> 0 | AA26: =COUNT(AA9:AA24) -> 0 | AE26: =COUNT(AE9:AE24) -> 0 | AI26: =COUNT(AI9:AI24) -> 0 | AM26: =COUNT(AM9:AM24) -> 0
A27: ABSENCES | C27: =COUNTIF(C9:C23,"Absent") -> 0 | G27: =COUNTIF(G9:G23,"Absent") -> 0 | K27: =COUNTIF(K9:K23,"Absent") -> 0 | O27: =COUNTIF(O9:O23,"Absent") -> 0 | S27: =COUNTIF(S9:S23,"Absent") -> 0 | W27: =COUNTIF(W9:W23,"Absent") -> 0 | AA27: =COUNTIF(AA9:AA23,"Absent") -> 0 | AE27: =COUNTIF(AE9:AE23,"Absent") -> 0 | AI27: =COUNTIF(AI9:AI23,"Absent") -> 0 | AM27: =COUNTIF(AM9:AM23,"Absent") -> 0
A28: VL | C28: =COUNTIF(C9:C23,"Leave")+COUNTIF(C9:C23,"VL") -> 0 | G28: =COUNTIF(G9:G23,"Leave")+COUNTIF(G9:G23,"VL") -> 0 | K28: =COUNTIF(K9:K23,"Leave")+COUNTIF(K9:K23,"VL") -> 0 | O28: =COUNTIF(O9:O23,"Leave")+COUNTIF(O9:O23,"VL") -> 0 | S28: =COUNTIF(S9:S23,"Leave")+COUNTIF(S9:S23,"VL") -> 0 | W28: =COUNTIF(W9:W23,"Leave")+COUNTIF(W9:W23,"VL") -> 0 | AA28: =COUNTIF(AA9:AA23,"Leave")+COUNTIF(AA9:AA23,"VL") -> 0 | AE28: =COUNTIF(AE9:AE23,"Leave")+COUNTIF(AE9:AE23,"VL") -> 0 | AI28: =COUNTIF(AI9:AI23,"Leave")+COUNTIF(AI9:AI23,"VL") -> 0 | AM28: =COUNTIF(AM9:AM23,"Leave")+COUNTIF(AM9:AM23,"VL") -> 0
A29: SL | C29: =COUNTIF(C9:C23,"SL") -> 0 | G29: =COUNTIF(G9:G23,"SL") -> 0 | K29: =COUNTIF(K9:K23,"SL") -> 0 | O29: =COUNTIF(O9:O23,"SL") -> 0 | S29: =COUNTIF(S9:S23,"SL") -> 0 | W29: =COUNTIF(W9:W23,"SL") -> 0 | AA29: =COUNTIF(AA9:AA23,"SL") -> 0 | AE29: =COUNTIF(AE9:AE23,"SL") -> 0 | AI29: =COUNTIF(AI9:AI23,"SL") -> 0 | AM29: =COUNTIF(AM9:AM23,"SL") -> 0
A30: ML | C30: =COUNTIF(C9:C23,"ML") -> 0 | G30: =COUNTIF(G9:G23,"ML") -> 0 | K30: =COUNTIF(K9:K23,"ML") -> 0 | O30: =COUNTIF(O9:O23,"ML") -> 0 | S30: =COUNTIF(S9:S23,"ML") -> 0 | W30: =COUNTIF(W9:W23,"ML") -> 0 | AA30: =COUNTIF(AA9:AA23,"ML") -> 0 | AE30: =COUNTIF(AE9:AE23,"ML") -> 0 | AI30: =COUNTIF(AI9:AI23,"ML") -> 0 | AM30: =COUNTIF(AM9:AM23,"ML") -> 0

Sheet TANGUB
A1: CHAPEL MANAGER MANAGER | C1: BARRICA JR., EDUARDO
A2: REGION | C2: MW1
A3: CHAPEL | C3: TANGUB
A4: PERIOD | C4: =CLEAN('SUMMARY_-_GCM'!D5) -> October 1-15, 2026
A7: DATE | C7: EDUARDO BARRICA | E7: Shifting Schedule | G7: ERNIE DICO | I7: Shifting Schedule | K7: JOEL PANTUJAN | M7: Shifting Schedule | O7: REY-AN BALATERO | Q7: Shifting Schedule | S7: MICHAEL ARCH DANIEL | U7: Shifting Schedule
A8: =CLEAN(BUUG!A8) -> # | B8: DAY | C8: IN | D8: OUT | E8: IN | F8: OUT | G8: IN | H8: OUT | I8: IN | J8: OUT | K8: IN | L8: OUT | M8: IN | N8: OUT | O8: IN | P8: OUT | Q8: IN | R8: OUT | S8: IN | T8: OUT | U8: IN | V8: OUT
A26: WORKED DAYS | C26: =COUNT(C9:C24) -> 0 | G26: =COUNT(G9:G24) -> 0 | K26: =COUNT(K9:K24) -> 0 | O26: =COUNT(O9:O24) -> 0 | S26: =COUNT(S9:S24) -> 0
A27: ABSENCES | C27: =COUNTIF(C9:C23,"Absent") -> 0 | G27: =COUNTIF(G9:G23,"Absent") -> 0 | K27: =COUNTIF(K9:K23,"Absent") -> 0 | O27: =COUNTIF(O9:O23,"Absent") -> 0 | S27: =COUNTIF(S9:S23,"Absent") -> 0
A28: VL | C28: =COUNTIF(C9:C23,"Leave")+COUNTIF(C9:C23,"VL") -> 0 | G28: =COUNTIF(G9:G23,"Leave")+COUNTIF(G9:G23,"VL") -> 0 | K28: =COUNTIF(K9:K23,"Leave")+COUNTIF(K9:K23,"VL") -> 0 | O28: =COUNTIF(O9:O23,"Leave")+COUNTIF(O9:O23,"VL") -> 0 | S28: =COUNTIF(S9:S23,"Leave")+COUNTIF(S9:S23,"VL") -> 0
A29: SL | C29: =COUNTIF(C9:C23,"SL") -> 0 | G29: =COUNTIF(G9:G23,"SL") -> 0 | K29: =COUNTIF(K9:K23,"SL") -> 0 | O29: =COUNTIF(O9:O23,"SL") -> 0 | S29: =COUNTIF(S9:S23,"SL") -> 0
A30: ML | C30: =COUNTIF(C9:C23,"ML") -> 0 | G30: =COUNTIF(G9:G23,"ML") -> 0 | K30: =COUNTIF(K9:K23,"ML") -> 0 | O30: =COUNTIF(O9:O23,"ML") -> 0 | S30: =COUNTIF(S9:S23,"ML") -> 0

Sheet OROQUIETA
A1: CHAPEL MANAGER MANAGER | C1: DELA CRUZ, GILBERT
A2: REGION | C2: MW1
A3: CHAPEL | C3: OROQUIETA
A4: PERIOD | C4: =CLEAN('SUMMARY_-_GCM'!D5) -> October 1-15, 2026
A7: DATE | C7: GILBERT DELA CRUZ | E7: Shifting Schedule | G7: JAY MATIAS | I7: Shifting Schedule | K7: JUSIL ANTIPUESTO | M7: Shifting Schedule | O7: HANZ CALAPIZ | Q7: Shifting Schedule | S7: EDDIE SONOGAN | U7: Shifting Schedule | W7: JUVEN ANTIPUESTO | Y7: Shifting Schedule
A8: =CLEAN(BUUG!A8) -> # | B8: DAY | C8: IN | D8: OUT | E8: IN | F8: OUT | G8: IN | H8: OUT | I8: IN | J8: OUT | K8: IN | L8: OUT | M8: IN | N8: OUT | O8: IN | P8: OUT | Q8: IN | R8: OUT | S8: IN | T8: OUT | U8: IN | V8: OUT | W8: IN | X8: OUT | Y8: IN | Z8: OUT
A26: WORKED DAYS | C26: =COUNT(C9:C24) -> 0 | G26: =COUNT(G9:G24) -> 0 | K26: =COUNT(K9:K24) -> 0 | O26: =COUNT(O9:O24) -> 0 | S26: =COUNT(S9:S24) -> 0 | W26: =COUNT(W9:W24) -> 0
A27: ABSENCES | C27: =COUNTIF(C9:C23,"Absent") -> 0 | G27: =COUNTIF(G9:G23,"Absent") -> 0 | K27: =COUNTIF(K9:K23,"Absent") -> 0 | O27: =COUNTIF(O9:O23,"Absent") -> 0 | S27: =COUNTIF(S9:S23,"Absent") -> 0 | W27: =COUNTIF(W9:W23,"Absent") -> 0
A28: VL | C28: =COUNTIF(C9:C23,"Leave")+COUNTIF(C9:C23,"VL") -> 0 | G28: =COUNTIF(G9:G23,"Leave")+COUNTIF(G9:G23,"VL") -> 0 | K28: =COUNTIF(K9:K23,"Leave")+COUNTIF(K9:K23,"VL") -> 0 | O28: =COUNTIF(O9:O23,"Leave")+COUNTIF(O9:O23,"VL") -> 0 | S28: =COUNTIF(S9:S23,"Leave")+COUNTIF(S9:S23,"VL") -> 0 | W28: =COUNTIF(W9:W23,"Leave")+COUNTIF(W9:W23,"VL") -> 0
A29: SL | C29: =COUNTIF(C9:C23,"SL") -> 0 | G29: =COUNTIF(G9:G23,"SL") -> 0 | K29: =COUNTIF(K9:K23,"SL") -> 0 | O29: =COUNTIF(O9:O23,"SL") -> 0 | S29: =COUNTIF(S9:S23,"SL") -> 0 | W29: =COUNTIF(W9:W23,"SL") -> 0
A30: ML | C30: {=SUM(COUNTIF(W9:W23,{"ML","PL"}))} -> 0 | G30: {=SUM(COUNTIF(W9:W23,{"ML","PL"}))} -> 0 | K30: {=SUM(COUNTIF(AA9:AA23,{"ML","PL"}))} -> 0 | O30: {=SUM(COUNTIF(AD9:AD23,{"ML","PL"}))} -> 0 | S30: {=SUM(COUNTIF(AG9:AG23,{"ML","PL"}))} -> 0 | W30: {=SUM(COUNTIF(AJ9:AJ23,{"ML","PL"}))} -> 0

Sheet IPIL
A1: CHAPEL MANAGER | C1: MARJORIE BAUTISTA
A2: REGION | C2: MW2
A3: CHAPEL | C3: IPIL
A4: PERIOD | C4: =CLEAN('SUMMARY_-_GCM'!D5) -> October 1-15, 2026
A7: DATE | C7: MARJORIE BAUTISTA | E7: Shifting Schedule | G7: DANIEL LAYOGUE | I7: Shifting Schedule | K7: GLESERIO PAQUIBO | M7: Shifting Schedule | O7: LOLIBOY ALMEDA | Q7: Shifting Schedule | S7: CARY VILLANO | U7: Shifting Schedule | W7: ROMANO CANTIGA | Y7: Shifting Schedule | AA7: ROLANDO MINDANG | AC7: Shifting Schedule
A8: =CLEAN(BUUG!A8) -> # | B8: DAY | C8: IN | D8: OUT | E8: IN | F8: OUT | G8: IN | H8: OUT | I8: IN | J8: OUT | K8: IN | L8: OUT | M8: IN | N8: OUT | O8: IN | P8: OUT | Q8: IN | R8: OUT | S8: IN | T8: OUT | U8: IN | V8: OUT | W8: IN | X8: OUT | Y8: IN | Z8: OUT | AA8: IN | AB8: OUT | AC8: IN | AD8: OUT
A26: WORKED DAYS | C26: =COUNT(C9:C24) -> 0 | G26: =COUNT(G9:G24) -> 0 | K26: =COUNT(K9:K24) -> 0 | O26: =COUNT(O9:O24) -> 0 | S26: =COUNT(S9:S24) -> 0 | W26: =COUNT(W9:W24) -> 0 | AA26: =COUNT(AA9:AA24) -> 0
A27: ABSENCES | C27: =COUNTIF(C9:C23,"Absent") -> 0 | G27: =COUNTIF(G9:G23,"Absent") -> 0 | K27: =COUNTIF(K9:K23,"Absent") -> 0 | O27: =COUNTIF(O9:O23,"Absent") -> 0 | S27: =COUNTIF(S9:S23,"Absent") -> 0 | W27: =COUNTIF(W9:W23,"Absent") -> 0 | AA27: =COUNTIF(AA9:AA23,"Absent") -> 0
A28: VL | C28: =COUNTIF(C9:C23,"Leave")+COUNTIF(C9:C23,"VL") -> 0 | G28: =COUNTIF(G9:G23,"Leave")+COUNTIF(G9:G23,"VL") -> 0 | K28: =COUNTIF(K9:K23,"Leave")+COUNTIF(K9:K23,"VL") -> 0 | O28: =COUNTIF(O9:O23,"Leave")+COUNTIF(O9:O23,"VL") -> 0 | S28: =COUNTIF(S9:S23,"Leave")+COUNTIF(S9:S23,"VL") -> 0 | W28: =COUNTIF(W9:W23,"Leave")+COUNTIF(W9:W23,"VL") -> 0 | AA28: =COUNTIF(AA9:AA23,"Leave")+COUNTIF(AA9:AA23,"VL") -> 0
A29: SL | C29: =COUNTIF(C9:C23,"SL") -> 0 | G29: =COUNTIF(G9:G23,"SL") -> 0 | K29: =COUNTIF(K9:K23,"SL") -> 0 | O29: =COUNTIF(O9:O23,"SL") -> 0 | S29: =COUNTIF(S9:S23,"SL") -> 0 | W29: =COUNTIF(W9:W23,"SL") -> 0 | AA29: =COUNTIF(AA9:AA23,"SL") -> 0
A30: ML | C30: {=SUM(COUNTIF(C9:C24,{"ML","PL","Maternal Leave","Paternity Leave"}))} -> 0 | G30: {=SUM(COUNTIF(G9:G24,{"ML","PL","Maternal Leave","Paternity Leave"}))} -> 0 | K30: {=SUM(COUNTIF(K9:K24,{"ML","PL","Maternal Leave","Paternity Leave"}))} -> 0 | O30: {=SUM(COUNTIF(O9:O24,{"ML","PL","Maternal Leave","Paternity Leave"}))} -> 0 | S30: {=SUM(COUNTIF(S9:S24,{"ML","PL","Maternal Leave","Paternity Leave"}))} -> 0 | W30: {=SUM(COUNTIF(W9:W24,{"ML","PL","Maternal Leave","Paternity Leave"}))} -> 0 | AA30: {=SUM(COUNTIF(AA9:AA24,{"ML","PL","Maternal Leave","Paternity Leave"}))} -> 0

Sheet ZAMBOANGA
A1: CHAPEL MANAGER | C1: MARIANO, EMMYLOU
A2: REGION | C2: MW2
A3: CHAPEL | C3: ZAMBOANGA
A4: PERIOD | C4: =CLEAN('SUMMARY_-_GCM'!D5) -> October 1-15, 2026
A7: DATE | C7: DENNIS Q. PAMARAN | E7: Shifting Schedule | G7: EMMYLOU MARIANO | I7: Shifting Schedule | K7: SHEILA VILLANO | M7: Shifting Schedule | O7: ROWELL MENDIJA | Q7: Shifting Schedule | S7: DANICA MAE LEDESMA | U7: Shifting Schedule | W7: LENIE MAY AUSEJO | Y7: Shifting Schedule | AA7: ADRIAN DR. SUSON | AC7: Shifting Schedule | AE7: JOVEN RENDON | AG7: Shifting Schedule | AI7: ELMER MONTEVERDE | AK7: Shifting Schedule | AM7: ROLANDO SAGOSO | AO7: Shifting Schedule | AQ7: ALBRICH ANDRADE | AS7: Shifting Schedule | AU7: ELVIN DAGALEA | AW7: Shifting Schedule | AY7: ROMEL MANUEL | BA7: Shifting Schedule | BC7: NELVIN DAGALEA | BE7: Shifting Schedule | BG7: GREGORIO MATIAS | BI7: Shifting Schedule | BK7: JESUS DELOS REYES | BM7: Shifting Schedule | BO7: JOEY DELA CRUZ | BQ7: Shifting Schedule | BS7: ELBERT JOHN FUTALAN | BU7: Shifting Schedule | BW7: SANTIE ALFON | BY7: Shifting Schedule | CA7: RAMIL LIMEN | CC7: Shifting Schedule | CE7: RICHIE DELA CRUZ | CG7: Shifting Schedule | CI7: EARL JOHN NAVARRO | CK7: Shifting Schedule | CM7: JERRY LLEDO | CO7: Shifting Schedule | CQ7: SUNNY CASTOR | CS7: Shifting Schedule | CU7: JEFFREY DELOS REYES | CW7: Shifting Schedule | CY7: OLIVER SUNURAN | DA7: Shifting Schedule
A8: =CLEAN(BUUG!A8) -> # | B8: DAY | C8: IN | D8: OUT | E8: IN | F8: OUT | G8: IN | H8: OUT | I8: IN | J8: OUT | K8: IN | L8: OUT | M8: IN | N8: OUT | O8: IN | P8: OUT | Q8: IN | R8: OUT | S8: IN | T8: OUT | U8: IN | V8: OUT | W8: IN | X8: OUT | Y8: IN | Z8: OUT | AA8: IN | AB8: OUT | AC8: IN | AD8: OUT | AE8: IN | AF8: OUT | AG8: IN | AH8: OUT | AI8: IN | AJ8: OUT | AK8: IN | AL8: OUT | AM8: IN | AN8: OUT | AO8: IN | AP8: OUT | AQ8: IN | AR8: OUT | AS8: IN | AT8: OUT | AU8: IN | AV8: OUT | AW8: IN | AX8: OUT | AY8: IN | AZ8: OUT | BA8: IN | BB8: OUT | BC8: IN | BD8: OUT | BE8: IN | BF8: OUT | BG8: IN | BH8: OUT | BI8: IN | BJ8: OUT | BK8: IN | BL8: OUT | BM8: IN | BN8: OUT | BO8: IN | BP8: OUT | BQ8: IN | BR8: OUT | BS8: IN | BT8: OUT | BU8: IN | BV8: OUT | BW8: IN | BX8: OUT | BY8: IN | BZ8: OUT | CA8: IN | CB8: OUT | CC8: IN | CD8: OUT | CE8: IN | CF8: OUT | CG8: IN | CH8: OUT | CI8: IN | CJ8: OUT | CK8: IN | CL8: OUT | CM8: IN | CN8: OUT | CO8: IN | CP8: OUT | CQ8: IN | CR8: OUT | CS8: IN | CT8: OUT | CU8: IN | CV8: OUT | CW8: IN | CX8: OUT | CY8: IN | CZ8: OUT | DA8: IN | DB8: OUT
A26: WORKED DAYS | C26: =COUNT(C9:C24) -> 0 | G26: =COUNT(G9:G24) -> 0 | K26: =COUNT(K9:K24) -> 0 | O26: =COUNT(O9:O24) -> 0 | S26: =COUNT(S9:S24) -> 0 | W26: =COUNT(W9:W24) -> 0 | AA26: =COUNT(AA9:AA24) -> 0 | AE26: =COUNT(AE9:AE24) -> 0 | AI26: =COUNT(AI9:AI24) -> 0 | AM26: =COUNT(AM9:AM24) -> 0 | AQ26: =COUNT(AQ9:AQ24) -> 0 | AU26: =COUNT(AU9:AU24) -> 0 | AY26: =COUNT(AY9:AY24) -> 0 | BC26: =COUNT(BC9:BC24) -> 0 | BG26: =COUNT(BG9:BG24) -> 0 | BK26: =COUNT(BK9:BK24) -> 0 | BO26: =COUNT(BO9:BO24) -> 0 | BS26: =COUNT(BS9:BS24) -> 0 | BW26: =COUNT(BW9:BW24) -> 0 | CA26: =COUNT(CA9:CA24) -> 0 | CE26: =COUNT(CE9:CE24) -> 0 | CI26: =COUNT(CI9:CI24) -> 0 | CM26: =COUNT(CM9:CM24) -> 0 | CQ26: =COUNT(CQ9:CQ24) -> 0 | CU26: =COUNT(CU9:CU24) -> 0 | CY26: =COUNT(CY9:CY24) -> 0
A27: ABSENCES | C27: =COUNTIF(C9:C23,"Absent") -> 0 | G27: =COUNTIF(G9:G23,"Absent") -> 0 | K27: =COUNTIF(K9:K23,"Absent") -> 0 | O27: =COUNTIF(O9:O23,"Absent") -> 0 | S27: =COUNTIF(S9:S23,"Absent") -> 0 | W27: =COUNTIF(W9:W23,"Absent") -> 0 | AA27: =COUNTIF(AA9:AA23,"Absent") -> 0 | AE27: =COUNTIF(AE9:AE23,"Absent") -> 0 | AI27: =COUNTIF(AI9:AI23,"Absent") -> 0 | AM27: =COUNTIF(AM9:AM23,"Absent") -> 0 | AQ27: =COUNTIF(AQ9:AQ23,"Absent") -> 0 | AU27: =COUNTIF(AU9:AU23,"Absent") -> 0 | AY27: =COUNTIF(AY9:AY23,"Absent") -> 0 | BC27: =COUNTIF(BC9:BC23,"Absent") -> 0 | BG27: =COUNTIF(BG9:BG23,"Absent") -> 0 | BK27: =COUNTIF(BK9:BK23,"Absent") -> 0 | BO27: =COUNTIF(BO9:BO23,"Absent") -> 0 | BS27: =COUNTIF(BS9:BS23,"Absent") -> 0 | BW27: =COUNTIF(BW9:BW23,"Absent") -> 0 | CA27: =COUNTIF(CA9:CA23,"Absent") -> 0 | CE27: =COUNTIF(CE9:CE23,"Absent") -> 0 | CI27: =COUNTIF(CI9:CI23,"Absent") -> 0 | CM27: =COUNTIF(CM9:CM23,"Absent") -> 0 | CQ27: =COUNTIF(CQ9:CQ23,"Absent") -> 0 | CU27: =COUNTIF(CU9:CU23,"Absent") -> 0 | CY27: =COUNTIF(CY9:CY23,"Absent") -> 0
A28: VL | C28: =COUNTIF(C9:C23,"Leave")+COUNTIF(C9:C23,"VL") -> 0 | G28: =COUNTIF(G9:G23,"Leave")+COUNTIF(G9:G23,"VL") -> 0 | K28: =COUNTIF(K9:K23,"Leave")+COUNTIF(K9:K23,"VL") -> 0 | O28: =COUNTIF(O9:O23,"Leave")+COUNTIF(O9:O23,"VL") -> 0 | S28: =COUNTIF(S9:S23,"Leave")+COUNTIF(S9:S23,"VL") -> 0 | W28: =COUNTIF(W9:W23,"Leave")+COUNTIF(W9:W23,"VL") -> 0 | AA28: =COUNTIF(AA9:AA23,"Leave")+COUNTIF(AA9:AA23,"VL") -> 0 | AE28: =COUNTIF(AE9:AE23,"Leave")+COUNTIF(AE9:AE23,"VL") -> 0 | AI28: =COUNTIF(AI9:AI24,"Leave")+COUNTIF(AI9:AI24,"VL") -> 0 | AM28: =COUNTIF(AM9:AM23,"Leave")+COUNTIF(AM9:AM23,"VL") -> 0 | AQ28: =COUNTIF(AQ9:AQ23,"Leave")+COUNTIF(AQ9:AQ23,"VL") -> 0 | AU28: =COUNTIF(AU9:AU23,"Leave")+COUNTIF(AU9:AU23,"VL") -> 0 | AY28: =COUNTIF(AY9:AY23,"Leave")+COUNTIF(AY9:AY23,"VL") -> 0 | BC28: =COUNTIF(BC9:BC23,"Leave")+COUNTIF(BC9:BC23,"VL") -> 0 | BG28: =COUNTIF(BG9:BG23,"Leave")+COUNTIF(BG9:BG23,"VL") -> 0 | BK28: =COUNTIF(BK9:BK23,"Leave")+COUNTIF(BK9:BK23,"VL") -> 0 | BO28: =COUNTIF(BO9:BO23,"Leave")+COUNTIF(BO9:BO23,"VL") -> 0 | BS28: =COUNTIF(BS9:BS23,"Leave")+COUNTIF(BS9:BS23,"VL") -> 0 | BW28: =COUNTIF(BW9:BW23,"Leave")+COUNTIF(BW9:BW23,"VL") -> 0 | CA28: =COUNTIF(CA9:CA23,"Leave")+COUNTIF(CA9:CA23,"VL") -> 0 | CE28: =COUNTIF(CE9:CE23,"Leave")+COUNTIF(CE9:CE23,"VL") -> 0 | CI28: =COUNTIF(CI9:CI23,"Leave")+COUNTIF(CI9:CI23,"VL") -> 0 | CM28: =COUNTIF(CM9:CM23,"Leave")+COUNTIF(CM9:CM23,"VL") -> 0 | CQ28: =COUNTIF(CQ9:CQ23,"Leave")+COUNTIF(CQ9:CQ23,"VL") -> 0 | CU28: =COUNTIF(CU9:CU23,"Leave")+COUNTIF(CU9:CU23,"VL") -> 0 | CY28: =COUNTIF(CY9:CY23,"Leave")+COUNTIF(CY9:CY23,"VL") -> 0
A29: SL | C29: =COUNTIF(C9:C23,"SL") -> 0 | G29: =COUNTIF(G9:G23,"SL") -> 0 | K29: =COUNTIF(K9:K23,"SL") -> 0 | O29: =COUNTIF(O9:O23,"SL") -> 0 | S29: =COUNTIF(S9:S23,"SL") -> 0 | W29: =COUNTIF(W9:W23,"SL") -> 0 | AA29: =COUNTIF(AA9:AA23,"SL") -> 0 | AE29: =COUNTIF(AE9:AE23,"SL") -> 0 | AI29: =COUNTIF(AI9:AI23,"SL") -> 0 | AM29: =COUNTIF(AM9:AM23,"SL") -> 0 | AQ29: =COUNTIF(AQ9:AQ23,"SL") -> 0 | AU29: =COUNTIF(AU9:AU23,"SL") -> 0 | AY29: =COUNTIF(AY9:AY23,"SL") -> 0 | BC29: =COUNTIF(BC9:BC23,"SL") -> 0 | BG29: =COUNTIF(BG9:BG23,"SL") -> 0 | BK29: =COUNTIF(BK9:BK23,"SL") -> 0 | BO29: =COUNTIF(BO9:BO23,"SL") -> 0 | BS29: =COUNTIF(BS9:BS23,"SL") -> 0 | BW29: =COUNTIF(BW9:BW23,"SL") -> 0 | CA29: =COUNTIF(CA9:CA23,"SL") -> 0 | CE29: =COUNTIF(CE9:CE23,"SL") -> 0 | CI29: =COUNTIF(CI9:CI23,"SL") -> 0 | CM29: =COUNTIF(CM9:CM23,"SL") -> 0 | CQ29: =COUNTIF(CQ9:CQ23,"SL") -> 0 | CU29: =COUNTIF(CU9:CU23,"SL") -> 0 | CY29: =COUNTIF(CY9:CY23,"SL") -> 0
A30: ML | C30: =COUNTIF(C9:C23,"ML") -> 0 | G30: =COUNTIF(G9:G23,"ML") -> 0 | K30: =COUNTIF(K9:K23,"ML") -> 0 | O30: =COUNTIF(O9:O23,"ML") -> 0 | S30: =COUNTIF(S9:S23,"ML") -> 0 | W30: =COUNTIF(W9:W23,"ML") -> 0 | AA30: =COUNTIF(AA9:AA23,"ML") -> 0 | AE30: =COUNTIF(AE9:AE23,"ML") -> 0 | AI30: =COUNTIF(AI9:AI23,"ML") -> 0 | AM30: =COUNTIF(AM9:AM23,"ML") -> 0 | AQ30: =COUNTIF(AQ9:AQ23,"ML") -> 0 | AU30: =COUNTIF(AU9:AU23,"ML") -> 0 | AY30: =COUNTIF(AY9:AY23,"ML") -> 0 | BC30: =COUNTIF(BC9:BC23,"ML") -> 0 | BG30: =COUNTIF(BG9:BG23,"ML") -> 0 | BK30: =COUNTIF(BK9:BK23,"ML") -> 0 | BO30: =COUNTIF(BO9:BO23,"ML") -> 0 | BS30: =COUNTIF(BS9:BS23,"ML") -> 0 | BW30: =COUNTIF(BW9:BW23,"ML") -> 0 | CA30: =COUNTIF(CA9:CA23,"ML") -> 0 | CE30: =COUNTIF(CE9:CE23,"ML") -> 0 | CI30: =COUNTIF(CI9:CI23,"ML") -> 0 | CM30: =COUNTIF(CM9:CM23,"ML") -> 0 | CQ30: =COUNTIF(CQ9:CQ23,"ML") -> 0 | CU30: =COUNTIF(CU9:CU23,"ML") -> 0 | CY30: =COUNTIF(CY9:CY23,"ML") -> 0
